Exception in thread "main" java.lang.RuntimeException: ZK Failover Controller failed: Failed to reEstablish connection with ZooKeeper
	at org.apache.hadoop.ha.ZKFailoverController.mainLoop(ZKFailoverController.java:364)
	at org.apache.hadoop.ha.ZKFailoverController.doRun(ZKFailoverController.java:235)
	at org.apache.hadoop.ha.ZKFailoverController.access$000(ZKFailoverController.java:60)
	at org.apache.hadoop.ha.ZKFailoverController$1.run(ZKFailoverController.java:169)
	at org.apache.hadoop.ha.ZKFailoverController$1.run(ZKFailoverController.java:165)
	at org.apache.hadoop.security.SecurityUtil.doAsLoginUserOrFatal(SecurityUtil.java:411)
	at org.apache.hadoop.ha.ZKFailoverController.run(ZKFailoverController.java:165)
	at org.apache.hadoop.hdfs.tools.DFSZKFailoverController.main(DFSZKFailoverController.java:180)
